module.exports = (fn) => {
  return (req, res, next) => {
    fn(req, res, next).catch((err) => {
      const errs = { ...err };
      console.log("âœ…âœ…âœ…ğŸ’¥ğŸ’¥ğŸ’¥", errs.properties, "ğŸ’¥ğŸ’¥ğŸ’¥ğŸ’¥");
      next(err);
    }); // this catch is callback runs when async task is rejected
  };
};
